Traceback (most recent call last):
  File "/opt/hostedtoolcache/Python/3.9.18/x64/lib/python3.9/site-packages/jupyter_cache/executors/utils.py", line 58, in single_nb_execution
    executenb(
  File "/opt/hostedtoolcache/Python/3.9.18/x64/lib/python3.9/site-packages/nbclient/client.py", line 1305, in execute
    return NotebookClient(nb=nb, resources=resources, km=km, **kwargs).execute()
  File "/opt/hostedtoolcache/Python/3.9.18/x64/lib/python3.9/site-packages/jupyter_core/utils/__init__.py", line 166, in wrapped
    return loop.run_until_complete(inner)
  File "/opt/hostedtoolcache/Python/3.9.18/x64/lib/python3.9/asyncio/base_events.py", line 647, in run_until_complete
    return future.result()
  File "/opt/hostedtoolcache/Python/3.9.18/x64/lib/python3.9/site-packages/nbclient/client.py", line 705, in async_execute
    await self.async_execute_cell(
  File "/opt/hostedtoolcache/Python/3.9.18/x64/lib/python3.9/site-packages/nbclient/client.py", line 1058, in async_execute_cell
    await self._check_raise_for_error(cell, cell_index, exec_reply)
  File "/opt/hostedtoolcache/Python/3.9.18/x64/lib/python3.9/site-packages/nbclient/client.py", line 914, in _check_raise_for_error
    raise CellExecutionError.from_cell_and_msg(cell, exec_reply_content)
nbclient.exceptions.CellExecutionError: An error occurred while executing the following cell:
------------------
import pmagpy.pmag as pmag
import pmagpy.ipmag as ipmag
import matplotlib.pyplot as plt
import smpsite as smp

import numpy as np
np.random.seed(666)

%matplotlib inline
------------------


[0;31m---------------------------------------------------------------------------[0m
[0;31mModuleNotFoundError[0m                       Traceback (most recent call last)
[0;32m/tmp/ipykernel_2117/438021193.py[0m in [0;36m?[0;34m()[0m
[0;32m----> 1[0;31m [0;32mimport[0m [0mpmagpy[0m[0;34m.[0m[0mpmag[0m [0;32mas[0m [0mpmag[0m[0;34m[0m[0;34m[0m[0m
[0m[1;32m      2[0m [0;32mimport[0m [0mpmagpy[0m[0;34m.[0m[0mipmag[0m [0;32mas[0m [0mipmag[0m[0;34m[0m[0;34m[0m[0m
[1;32m      3[0m [0;32mimport[0m [0mmatplotlib[0m[0;34m.[0m[0mpyplot[0m [0;32mas[0m [0mplt[0m[0;34m[0m[0;34m[0m[0m
[1;32m      4[0m [0;32mimport[0m [0msmpsite[0m [0;32mas[0m [0msmp[0m[0;34m[0m[0;34m[0m[0m

[0;32m/opt/hostedtoolcache/Python/3.9.18/x64/lib/python3.9/site-packages/pmagpy/__init__.py[0m in [0;36m?[0;34m()[0m
[1;32m     20[0m [0;34m[0m[0m
[1;32m     21[0m [0mThanks[0m[0;31m![0m[0;34m[0m[0;34m[0m[0m
[1;32m     22[0m [0;34m[0m[0m
[1;32m     23[0m """.format(sys.version))
[0;32m---> 24[0;31m [0;32mfrom[0m [0;34m.[0m [0;32mimport[0m [0mpmag[0m[0;34m[0m[0;34m[0m[0m
[0m[1;32m     25[0m [0;32mfrom[0m [0;34m.[0m [0;32mimport[0m [0mipmag[0m[0;34m[0m[0;34m[0m[0m
[1;32m     26[0m [0;32mfrom[0m [0;34m.[0m [0;32mimport[0m [0mpmagplotlib[0m[0;34m[0m[0;34m[0m[0m
[1;32m     27[0m [0;32mfrom[0m [0;34m.[0m [0;32mimport[0m [0mfind_pmag_dir[0m[0;34m[0m[0;34m[0m[0m

[0;32m/opt/hostedtoolcache/Python/3.9.18/x64/lib/python3.9/site-packages/pmagpy/pmag.py[0m in [0;36m?[0;34m()[0m
[1;32m      5[0m [0;32mimport[0m [0mos[0m[0;34m[0m[0;34m[0m[0m
[1;32m      6[0m [0;32mimport[0m [0mstring[0m[0;34m[0m[0;34m[0m[0m
[1;32m      7[0m [0;32mimport[0m [0msys[0m[0;34m[0m[0;34m[0m[0m
[1;32m      8[0m [0;32mimport[0m [0mtime[0m[0;34m[0m[0;34m[0m[0m
[0;32m----> 9[0;31m [0;34m[0m[0m
[0m[1;32m     10[0m [0;32mfrom[0m [0mpast[0m[0;34m.[0m[0mutils[0m [0;32mimport[0m [0mold_div[0m[0;34m[0m[0;34m[0m[0m
[1;32m     11[0m [0;32mimport[0m [0mnumpy[0m [0;32mas[0m [0mnp[0m[0;34m[0m[0;34m[0m[0m
[1;32m     12[0m [0;32mfrom[0m [0mnumpy[0m [0;32mimport[0m [0mrandom[0m[0;34m[0m[0;34m[0m[0m

[0;31mModuleNotFoundError[0m: No module named 'past'

